[{"name": "unittest.loader._FailedTest.test.test_tasks", "status": "errored", "message": "Failed to import test module: test.test_tasks\nTraceback (most recent call last):\n  File \"C:\\Users\\Alii_\\miniconda3\\lib\\unittest\\loader.py\", line 436, in _find_test_path\n    module = self._get_module_from_name(name)\n  File \"C:\\Users\\Alii_\\miniconda3\\lib\\unittest\\loader.py\", line 377, in _get_module_from_name\n    __import__(name)\n  File \"C:\\Users\\Alii_\\Desktop\\MOOC\\mooc-securing-software-21\\part2-07.tasks\\test\\test_tasks.py\", line 12, in <module>\n    from selenium import webdriver\nModuleNotFoundError: No module named 'selenium'\n", "passed": false, "points": [], "backtrace": ["  File \"C:\\Users\\Alii_\\miniconda3\\lib\\unittest\\case.py\", line 60, in testPartExecutor\n    yield\n", "  File \"C:\\Users\\Alii_\\miniconda3\\lib\\unittest\\case.py\", line 676, in run\n    self._callTestMethod(testMethod)\n", "  File \"C:\\Users\\Alii_\\miniconda3\\lib\\unittest\\case.py\", line 633, in _callTestMethod\n    method()\n", "  File \"C:\\Users\\Alii_\\miniconda3\\lib\\unittest\\loader.py\", line 34, in testFailure\n    raise self._exception\n"]}]